Workbook

Sheet Controls
A1: Forecast: Kundennamen
A2: {=MID(CELL("dateiname",A1),SEARCH("]",CELL("dateiname",A1))+1,31)} -> Controls
A3: (TEUR) | B3: =Controls!B7 -> 45291 | C3: =DATE(YEAR(B3)+1,MONTH(B3),DAY(B3)) -> 45657 | D3: =DATE(YEAR(C3)+1,MONTH(C3),DAY(C3)) -> 46022 | E3: =DATE(YEAR(D3)+1,MONTH(D3),DAY(D3)) -> 46387 | F3: =DATE(YEAR(E3)+1,MONTH(E3),DAY(E3)) -> 46752 | G3: =DATE(YEAR(F3)+1,MONTH(F3),DAY(F3)) -> 47118 | H3: =DATE(YEAR(G3)+1,MONTH(G3),DAY(G3)) -> 47483 | I3: =DATE(YEAR(H3)+1,MONTH(H3),DAY(H3)) -> 47848
A5: Tage pro Jahr | B5: 365
A6: Circular Switch | B6: 1 | C6: (1 = Kreislauf läuft, 0 = ausgesetzt) - Interation muss aktiviert sein!
A7: Erstes Ausgangsjahr | B7: 45291
A9: Erläuterungen zur Formatierung:
A10: Formatierung: | C10: Erklärung:
A11: Format | C11: Direkteingaben, belegte Zahlenwerte, hard code
A12: Format | C12: Verlinkte Werte
A13: Format | C13: Input, Eine Annahme
A14: Format | C14: Verlinkte Werte aus agree-Daten (Input)
A15: -100 | C15: Negativer Wert / Liqui-Abfluss
A18: Betriebswirtschaftliche Kennzahlen: | C18: Erklärung: | K18: Standardwerte
A19: Eigenkapitalquote: | G19: 25 | H19: 0-25% | I19: <0%
A20: Kreditorenziel | C20: VLLL / MA * Feld 5B (Tage eines Jahres) | G20: <50 Tage | H20: >50 Tage | I20: -
A21: Liquidität ersten Grades | C21: Finanzmittel / kurz. Fremdkapital * 100 | G21: >15% | H21: <15% | I21: - | K21: 35.9652
A22: EBTDA-Marge | C22: EBTDA / Gesamtleistung * 100 | G22: >7% | H22: <7% | I22: <0
A23: Umschlagshäufigkeit | C23: MA / Vorräte | G23: >3 | H23: <3 | I23: 0
A24: Fremdkapitalstruktur | C24: Kurzfr. FK / (langfr. FK + kurzfr. FK) | G24: <5% | H24: >5%
A25: Zinsdeckungsgrad | C25: ecf / Zinskosten | G25: 1 | H25: 1 - 25 | I25: 25
A26: EBT (BE vor EESt.) | C26: "Wird Geld verdient" | G26: >45 TEUR | H26: >0 | I26: <0
A27: Anlagedeckungsgrad | C27: Wie langfristig ist das AV finanziert? | G27: >110% | H27: <110% | I27: <75

Sheet Input (agree Daten)
A1: Stammdaten
A2: Kunden Bilanz-Auswertung Auswertungstyp Standard
A3: Personennummer: | C3: Abschlusszeitraum | D3: 01.01.2024 - 31.12.2024 | E3: Bilanzjahr | F3: 2024
A4: Kunde: | C4: Bilanz-Art: | D4: HGB Handelsbilanz | E4: Datum der Erfassung: | F4: 45707
C5: GuV-Art: | D5: Gesamtkostenverfahren | E5: Datum letzte Änderung: | F5: 46057.467
A6: Strasse: | C6: Steuerberater: | D6: nicht vorhanden | E6: Konsolidierung: | F6: nicht konsolidiert
A7: Ort: | C7: Erstellung durch: | D7: Steuerberater/-bevollmächtigter | E7: Bilanztyp: | F7: Einzelbilanz
A8: Rechtsform: | C8: Branche: | D8: 1412 Garten- und Landschaftsbau
C9: Status: | D9: Für Rating freigegeben | E9: Beträge in: | F9: T-EUR
C10: Herkunft: | D10: Einreichung Kunde | E10: Zeitraum-Typ: | F10: Ganzjährig
C11: Testatart: | D11: Erstellung ohne Beurteilungen | E11: Berater: | F11: Benedikt Zoller
C12: Größenklasse Bilanz: | D12: 2.501 - 6.000 T-EUR | E12: Bezeichnung:
A13: Die Branchendaten wurden auf folgender Basis ermittelt:
A14: Branchenschlüssel: | B14: 1412 Garten- und Landschaftsbau
A15: Branchendaten sind aus dem Jahr: | B15: 2024 | C15: Größenklasse: | D15: 2.501 - 6.000 T-EUR | E15: Verarbeitete Bilanzen: | F15: 58
A18: Kurzinformation
C19: HGB Handelsbilanz | E19: HGB Handelsbilanz | G19: Abw. Vorjahr | H19: Branche
C20: 2023 | E20: 2024 | H20: 2024
C21: TEUR | D21: % | E21: TEUR | F21: % | G21: % | H21: %
A22: Grundstücke und Gebäude | B22: 11022 | C22: 2466.1 | D22: 51.8 | E22: 2437.6 | F22: 50.1 | G22: -1.2
A23: Sachanlagen | B23: 11049 | C23: 3810.8 | D23: 80 | E23: 4061.7 | F23: 83.4 | G23: 6.6 | H23: 26.1
A24: Finanzanlagen | B24: 11179
A25: Anlagevermögen | B25: 11189 | C25: 3813.6 | D25: 80.1 | E25: 4065.9 | F25: 83.5 | G25: 6.6 | H25: 26.6
A26: Erhaltene Anzahlungen (offen abgesetzt) | B26: 11228 | C26: 386 | D26: 8.1 | E26: 201.7 | F26: 4.1 | G26: -47.8
A27: davon Abschlagszahlungen | B27: 11230
A28: Vorräte | B28: 11249 | C28: 41 | D28: 0.9 | E28: 105.7 | F28: 2.2 | G28: 157.8 | H28: 34.3
A29: Ford. a. LuL | B29: 11291 | C29: 834.2 | D29: 17.5 | E29: 546.9 | F29: 11.2 | G29: -34.4 | H29: 15.5
A30: Finanzmittel | B30: 11369 | C30: 26.4 | D30: 0.6 | E30: 34.5 | F30: 0.7 | G30: 30.7 | H30: 5.5
A31: UV-kfr. Vermögensgegenstände/-werte | B31: 11379 | C31: 938.5 | D31: 19.7 | E31: 760.9 | F31: 15.6 | G31: -18.9 | H31: 71.8
A32: Bilanzsumme - bereinigt (AKTIVA) | B32: 11500 | C32: 4761.8 | D32: 100 | E32: 4868.9 | F32: 100 | G32: 2.3
A33: Ausgewiesenes Eigenkapital | B33: 12099 | C33: 122 | D33: 2.6 | E33: 141.3 | F33: 2.9 | G33: 15.8
A34: Wirtschaftliches Eigenkapital | B34: 12169 | C34: 95.9 | D34: 2 | E34: 100 | F34: 2 | G34: 4.3 | H34: 17.2
A35: Verbindlichkeiten gegenüber Kreditinstituten | B35: 12214 | C35: 3414.5 | D35: 71.7 | E35: 3382.5 | F35: 69.5 | G35: -0.9 | H35: 10.3
A36: Langfristiges Fremdkapital | B36: 12299 | C36: 3741.9 | D36: 78.6 | E36: 4206.2 | F36: 86.4 | G36: 12.4 | H36: 14.4
A37: Verb. ggü. KI bis 1 Jahr | B37: 12342 | C37: 259.9 | D37: 5.5 | E37: 69.9 | F37: 1.4 | G37: -73.1 | H37: 0.3
A38: Verb. a. LuL b. 1J | B38: 12371 | C38: 287.6 | D38: 6 | E38: 214.4 | F38: 4.4 | G38: -25.4 | H38: 5.8
A39: Kurzfristiges Fremdkapital | B39: 12409 | C39: 924 | D39: 19.4 | E39: 562.7 | F39: 11.6 | G39: -39.1 | H39: 56.8
A40: Umsatzerlöse | B40: 13001
A41: Gesamtleistung | B41: 13059 | C41: 3985.1 | D41: 100 | E41: 4214.9 | F41: 100 | G41: 5.8
A42: Rohergebnis | B42: 13139 | C42: 2725.8 | D42: 68.4 | E42: 3152 | F42: 74.8 | G42: 15.6 | H42: 64.4
...

Sheet Mapping
A1: Mapping-Tabelle: Input → Modell
A2: Jede Zeile zeigt, wohin eine Input-Position im Modell fließt. „Davon“-Zeilen und Zwischensummen sind bewusst nicht verlinkt (Transparenz-Zeilen). WICHTIG: Die GuV ist bereinigt – Unregelmäßige Posten (13351-13469, 13529) sind BEWUSST AUSGESCHLOSSEN, um eine nachhaltige Forecast-Basis zu gewinnen. EBT und Net Income weichen daher systematisch von agree (13539/13549) ab.
A4: Input-Bezeichnung | B4: Pos.-Nr. | C4: Input-Zeile | D4: Ziel-Sheet | E4: Ziel-Zelle (Zeile) | F4: Modell-Position | G4: Hinweis
A5: --- AKTIVA ---
A6: Selbst gesch. Schutz- u. ähnl. Rechte und Werte/ Entwicklungskost. | B6: 11001 | C6: 60 | D6: Bilanz | E6: 7 | F6: Immaterielle Vermögenswerte
A7: Entg. erworb. Konz., gew. Schutz- u. ähnl. Rechte u. Werte sowie Lizenzen | B7: 11002 | C7: 61 | D7: Bilanz | E7: 7 | F7: Immaterielle Vermögenswerte
A8: Geschäfts- oder Firmenwert | B8: 11003 | C8: 62 | D8: Bilanz | E8: 7 | F8: Immaterielle Vermögenswerte
A9: Gel. Anz. a. imm. Vermögensgegenstände/-werte | B9: 11005 | C9: 63 | D9: Bilanz | E9: 7 | F9: Immaterielle Vermögenswerte
A10: Immaterielle Vermögensgegenstände/-werte | B10: 11019 | C10: 64 | D10: — | E10: — | F10: — | G10: Zwischensumme – nicht verlinkt (wird im Modell neu summiert)
A11: Grundstücke und Gebäude | B11: 11022 | C11: 65 | D11: Bilanz | E11: 8 | F11: Sachanlagevermögen
A12: Technische Anlagen und Maschinen | B12: 11025 | C12: 66 | D12: Bilanz | E12: 8 | F12: Sachanlagevermögen
A13: And. Anlagen und BGA | B13: 11028 | C13: 67 | D13: Bilanz | E13: 8 | F13: Sachanlagevermögen
A14: Gel. Anz. u. Anl. im Bau | B14: 11032 | C14: 68 | D14: Bilanz | E14: 8 | F14: Sachanlagevermögen
A15: Sachanlagen | B15: 11049 | C15: 69 | D15: — | E15: — | F15: — | G15: Zwischensumme – nicht verlinkt
A16: Imm. Vermögensg./-werte, Sachanl., Nutzungsrechte... | B16: 11129 | C16: 70 | D16: — | E16: — | F16: — | G16: Zwischensumme – nicht verlinkt
A17: At-Equity-Beteiligungen | B17: 11131 | C17: 71 | D17: Bilanz | E17: 9 | F17: Sonstige Anlagegüter
A18: Anteile an verbundenen Unternehmen (AV) | B18: 11132 | C18: 72 | D18: Bilanz | E18: 9 | F18: Sonstige Anlagegüter
A19: Ausl. an verb. Unt. (AV) | B19: 11133 | C19: 73 | D19: Bilanz | E19: 9 | F19: Sonstige Anlagegüter
A20: Anteile an Beteiligungsunternehmen | B20: 11134 | C20: 74 | D20: Bilanz | E20: 9 | F20: Sonstige Anlagegüter
A21: Ausleihungen an Beteiligungsunternehmen | B21: 11135 | C21: 75 | D21: Bilanz | E21: 9 | F21: Sonstige Anlagegüter
A22: At-Equity-Bet., Ant. u. Ausl. a. Verb.- und Beteiligungsuntern. | B22: 11149 | C22: 76 | D22: — | F22: — | G22: Zwischensumme – nicht verlinkt
A23: Wertpapiere des Anlagevermögens, Genossenschaftsanteile | B23: 11151 | C23: 77 | D23: Bilanz | E23: 9 | F23: Sonstige Anlagegüter
A24: Sonstige Ausleihungen | B24: 11152 | C24: 78 | D24: Bilanz | E24: 9 | F24: Sonstige Anlagegüter
A25: Sonstige Finanzanlagen | B25: 11169 | C25: 79 | D25: — | F25: — | G25: Zwischensumme – nicht verlinkt
A26: Finanzanlagen | B26: 11179 | C26: 80 | D26: — | F26: — | G26: Zwischensumme – nicht verlinkt
A27: Anlagevermögen | B27: 11189 | C27: 81 | D27: — | F27: — | G27: Summenposition – nicht verlinkt
A28: Roh-, Hilfs- und Betriebsstoffe | B28: 11221 | C28: 82 | D28: Bilanz | E28: 12 | F28: Vorräte
A29: Unfertige Erzeugnisse, unfertige Leistungen | B29: 11222 | C29: 83 | D29: Bilanz | E29: 12 | F29: Vorräte
A30: Erhaltene Anzahlungen (offen abgesetzt) | B30: 11228 | C30: 84 | D30: Bilanz | E30: 12 | F30: Vorräte | G30: Negativposten in Vorräten
A31: davon Abschlagszahlungen | B31: 11230 | C31: 85 | D31: — | F31: — | G31: davon-Position – nicht verlinkt (Transparenz)
A32: Fertige Erzeugnisse | B32: 11224 | C32: 86 | D32: Bilanz | E32: 12 | F32: Vorräte
A33: Waren | B33: 11225 | C33: 87 | D33: Bilanz | E33: 12 | F33: Vorräte
A34: Geleistete Anzahlungen | B34: 11226 | C34: 88 | D34: Bilanz | E34: 12 | F34: Vorräte
A35: Vorräte | B35: 11249 | C35: 89 | D35: — | F35: — | G35: Summenposition – nicht verlinkt
A36: Ford. a. LuL | B36: 11291 | C36: 90 | D36: Bilanz | E36: 13 | F36: Forderungen aus L+L
A37: Ford. ggü. verb. Unt. | B37: 11294 | C37: 91 | D37: Bilanz | E37: 14 | F37: Sonstiges Umlaufvermögen
A38: Ford. ggü. Beteiligungsuntern. | B38: 11295 | C38: 92 | D38: Bilanz | E38: 14 | F38: Sonstiges Umlaufvermögen
A39: Ausst. Einl., eingef., aber n. n. eingez. | B39: 11296 | C39: 93 | D39: Bilanz | E39: 14 | F39: Sonstiges Umlaufvermögen
A40: Forderungen gegenüber Gesellschaftern | B40: 11297 | C40: 94 | D40: Bilanz | E40: 14 | F40: Sonstiges Umlaufvermögen
A41: Sonstige Vermögensgegenstände/-werte | B41: 11298 | C41: 95 | D41: Bilanz | E41: 14 | F41: Sonstiges Umlaufvermögen
...

Sheet Input (Annahmen)
A1: =Controls!A1 -> Forecast: Kundennamen
A2: {=MID(CELL("dateiname",A1),SEARCH("]",CELL("dateiname",A1))+1,31)} -> Input (Annahmen)
A3: (TEUR) | B3: =Controls!B7 -> 45291 | C3: =DATE(YEAR(B3)+1,MONTH(B3),DAY(B3)) -> 45657 | D3: =DATE(YEAR(C3)+1,MONTH(C3),DAY(C3)) -> 46022 | E3: =DATE(YEAR(D3)+1,MONTH(D3),DAY(D3)) -> 46387 | F3: =DATE(YEAR(E3)+1,MONTH(E3),DAY(E3)) -> 46752 | G3: =DATE(YEAR(F3)+1,MONTH(F3),DAY(F3)) -> 47118 | H3: =DATE(YEAR(G3)+1,MONTH(G3),DAY(G3)) -> 47483 | I3: =DATE(YEAR(H3)+1,MONTH(H3),DAY(H3)) -> 47848 | K3: Erläuterungen
A5: Annahmen zur GuV
A6: Wachstum Gesamtleistung in % | C6: =GuV!C7/GuV!B7-1 -> 0.057664801 | D6: 0.05 | E6: 0.05 | F6: 0.05 | G6: 0.05 | H6: 0.05 | I6: 0.05 | K6: Konstantes Wachstum, jedoch weniger dynamisch
A7: Materialaufwandsquote | B7: =GuV!B8/GuV!B7 -> -0.31600211 | C7: =GuV!C8/GuV!C7 -> -0.2521768 | D7: -0.3 | E7: -0.29 | F7: -0.29 | G7: -0.29 | H7: =G7 -> -0.29 | I7: =H7 -> -0.29 | K7: Durch die neu erteilte BImSchG-Genehmigung können auf dem Betriebshof Materialen recycelt werden
A8: Personalaufwandsquote | B8: =GuV!B11/GuV!B7 -> -0.30468495 | C8: =GuV!C11/GuV!$C$7 -> -0.337422 | D8: -0.32 | E8: =D8 -> -0.32 | F8: =E8 -> -0.32 | G8: =F8 -> -0.32 | H8: =G8 -> -0.32 | I8: =H8 -> -0.32 | K8: Leichter Anstieg aufgrund höherem Personaleinsatz erwartet
A9: Raumkosten, in % der Gesamtleistung | B9: =GuV!B12/GuV!$B$7 -> 0 | C9: =GuV!C12/GuV!$C$7 -> 0 | D9: -0.014 | E9: =D9 -> -0.014 | F9: =E9 -> -0.014 | G9: =F9 -> -0.014 | H9: =G9 -> -0.014 | I9: =H9 -> -0.014 | K9: Analog 2023, keine Veränderungen geplant
A10: Kosten für Versicherungen und Beiträge, in % der Gesamtleistung | B10: =GuV!B13/GuV!$B$7 -> 0 | C10: =GuV!C13/GuV!$C$7 -> 0 | D10: -0.013 | E10: =D10 -> -0.013 | F10: =E10 -> -0.013 | G10: =F10 -> -0.013 | H10: =G10 -> -0.013 | I10: =H10 -> -0.013
A11: Kosten für Reperatur und Instanthaltung, in % der Gesamtleistung | B11: =GuV!B14/GuV!$B$7 -> 0 | C11: =GuV!C14/GuV!$C$7 -> 0 | D11: -0.0325 | E11: -0.0325 | F11: =E11 -> -0.0325 | G11: =F11 -> -0.0325 | H11: =G11 -> -0.0325 | I11: =H11 -> -0.0325 | K11: 2024 wurde eine eigene Werkstatt auf dem Betriebsgelände eingerichtet
A12: Fahrzeugkosten, in % der Gesamtleistung | B12: =GuV!B15/GuV!$B$7 -> 0 | C12: =GuV!C15/GuV!$C$7 -> 0 | D12: -0.097 | E12: =D12 -> -0.097 | F12: =E12 -> -0.097 | G12: =F12 -> -0.097 | H12: =G12 -> -0.097 | I12: =H12 -> -0.097 | K12: Konstante Entwicklung auf Niveau der Vorjahre erwartet
A13: Werbe- und Reisekosten, in % der Gesamtleistung | B13: =GuV!B16/GuV!$B$7 -> 0 | C13: =GuV!C16/GuV!$C$7 -> 0 | D13: -0.008 | E13: =D13 -> -0.008 | F13: =E13 -> -0.008 | G13: =F13 -> -0.008 | H13: =G13 -> -0.008 | I13: =H13 -> -0.008
A14: Verschiedene betr. Kosten, in % der Gesamtleistung | B14: =GuV!B17/GuV!$B$7 -> -0.23065921 | C14: =GuV!C17/GuV!$C$7 -> -0.24766898 | D14: -0.055 | E14: =D14 -> -0.055 | F14: =E14 -> -0.055 | G14: =F14 -> -0.055 | H14: =G14 -> -0.055 | I14: =H14 -> -0.055 | K14: Annahme auf Basis der Vorjahre
A15: Steuerquote | B15: =GuV!B27/GuV!B25 -> -0.15 | C15: =GuV!C27/GuV!C25 -> -0.050892267 | D15: -0.261 | E15: -0.3 | F15: -0.35 | G15: =F15 -> -0.35 | H15: -0.37 | I15: =H15 -> -0.37
A16: Vergütung für stille Gesellschafter in % vom BE nach Steuern
A19: Annahmen zur Bilanz
A20: Sonstige Anlagegüter | B20: =Bilanz!B9 -> 0 | C20: =Bilanz!C9 -> 0 | D20: 0 | E20: =D20 -> 0 | F20: =E20 -> 0 | G20: =F20 -> 0 | H20: =G20 -> 0 | I20: =H20 -> 0
A21: Sonstiges Umlaufvermögen | B21: =Bilanz!B14 -> 46.6 | C21: =Bilanz!C14 -> 115.9 | D21: =C21 -> 115.9 | E21: =D21 -> 115.9 | F21: =E21 -> 115.9 | G21: =F21 -> 115.9 | H21: =G21 -> 115.9 | I21: =H21 -> 115.9
A22: Betriebsnotwendige Liquidität in % der Gesamtleistung | B22: =Bilanz!B16/GuV!B7 -> 0.0066246769 | C22: =Bilanz!C16/GuV!C7 -> 0.0081852476 | D22: 0.011 | E22: =D22 -> 0.011 | F22: =E22 -> 0.011 | G22: =F22 -> 0.011 | H22: =G22 -> 0.011 | I22: =H22 -> 0.011
A23: Stammkapital / gez. Kapital | B23: =Bilanz!B24 -> -20.3 | C23: =Bilanz!C24 -> -41.8 | D23: =C23 -> -41.8 | E23: =D23 -> -41.8 | F23: =E23 -> -41.8 | G23: =F23 -> -41.8 | H23: =G23 -> -41.8 | I23: =H23 -> -41.8
A24: Rücklagen | B24: =Bilanz!B25 -> 91.3 | C24: =Bilanz!C25 -> 91.3 | D24: =C24 -> 91.3 | E24: =D24 -> 91.3 | F24: =E24 -> 91.3 | G24: =F24 -> 91.3 | H24: =G24 -> 91.3 | I24: =H24 -> 91.3
A25: Pensionsrückstellungen in % der Gesamtleistung | B25: =Bilanz!B32/GuV!B7 -> 0 | C25: =Bilanz!C32/GuV!C7 -> 0 | D25: =AVERAGE(B25:C25) -> 0 | E25: =D25 -> 0 | F25: =E25 -> 0 | G25: =F25 -> 0 | H25: =G25 -> 0 | I25: =H25 -> 0
A26: Andere langfristige Verbindlichkeiten | B26: =Bilanz!B34 -> 327.4 | C26: =Bilanz!C34 -> 823.7 | D26: =C26 -> 823.7 | E26: =D26 -> 823.7 | F26: =E26 -> 823.7 | G26: =F26 -> 823.7 | H26: =G26 -> 823.7 | I26: =H26 -> 823.7
A27: Andere kurzfristige Verbindlichkeiten | B27: =Bilanz!B40 -> 376.5 | C27: =Bilanz!C40 -> 278.4 | D27: =GuV!D7*0.17 -> 752.35965 | E27: =GuV!E7*0.17 -> 789.97763 | F27: =GuV!F7*0.17 -> 829.47651 | G27: =GuV!G7*0.17 -> 870.95034 | H27: =GuV!H7*0.17 -> 914.49786 | I27: =GuV!I7*0.17 -> 960.22275 | K27: Anzahlungen werden künftig durchgesetzt
A29: Weitere Annahmen
A30: Investitionen in immat. Vermögenswerte in % der Gesamtleistung | C30: ='Side Calcs'!C7/GuV!C7 -> 0.00066430995 | D30: =C30 -> 0.00066430995 | E30: =D30 -> 0.00066430995 | F30: =E30 -> 0.00066430995 | G30: =F30 -> 0.00066430995 | H30: =G30 -> 0.00066430995 | I30: =H30 -> 0.00066430995
A31: Abschreibungsquote der immat. Vermögenswerte pro Jahr | D31: 0.33 | E31: =D31 -> 0.33 | F31: =E31 -> 0.33 | G31: =F31 -> 0.33 | H31: =G31 -> 0.33 | I31: =H31 -> 0.33
A32: Investitionen in das Sachanlagevermögen in % der Gesamtleistung | C32: ='Side Calcs'!C13/GuV!C7 -> 0.072291158 | D32: 0.08 | E32: =D32 -> 0.08 | F32: 0.08 | G32: =F32 -> 0.08 | H32: =G32 -> 0.08 | I32: =H32 -> 0.08
A33: Abschreibungsquote des Sachanlagevermögens in % | C33: ='Side Calcs'!C14/'Side Calcs'!C12 -> -0.1132833 | D33: =C33 -> -0.1132833 | E33: =D33 -> -0.1132833 | F33: =E33 -> -0.1132833 | G33: =F33 -> -0.1132833 | H33: =G33 -> -0.1132833 | I33: =H33 -> -0.1132833
A34: Lagerdauer im Durchschnitt in Tage | B34: ='Side Calcs'!B19 -> 11.883586 | C34: ='Side Calcs'!C19 -> 36.297394 | D34: 12.6 | E34: =D34 -> 12.6 | F34: =E34 -> 12.6 | G34: =F34 -> 12.6 | H34: =G34 -> 12.6 | I34: =H34 -> 12.6 | K34: Unfertige Leistungen in 2023, in der Planung nicht vorgesehen
A35: Debitorenziel | B35: ='Side Calcs'!B22 -> 76.40536 | C35: ='Side Calcs'!C22 -> 47.360198 | D35: 90 | E35: =D35 -> 90 | F35: =E35 -> 90 | G35: =F35 -> 90 | H35: =G35 -> 90 | I35: =H35 -> 90 | K35: Durchschnittswert der letzten 2 Jahresabschlüsse
A36: Kreditorenziel | B36: ='Side Calcs'!B25 -> 83.359009 | C36: ='Side Calcs'!C25 -> 73.624988 | D36: 30 | E36: =D36 -> 30 | F36: =E36 -> 30 | G36: =F36 -> 30 | H36: =G36 -> 30 | I36: =H36 -> 30 | K36: Zielwert auf 30 Tage angepasst, durch BAYBG finanziert
A37: Ausschüttungen / Privatentnahmen in % des Nettobetriebsergebnisses | C37: ='Side Calcs'!C32/'Side Calcs'!C31 -> 0 | D37: -75 | E37: =D37*1.05 -> -78.75 | F37: =E37*1.05 -> -82.6875 | G37: =F37*1.05 -> -86.821875 | H37: =G37*1.05 -> -91.162969 | I37: =H37*1.05 -> -95.721117 | K37: Inflationsangepasste Ausschüttung
A38: Aufnahme von Nachrangkapital in EUR | D38: 140 | E38: 0 | F38: 0 | G38: 0 | H38: 0 | I38: 0
A39: Vorgesehene Tilgung von Nachrangkapital in EUR | D39: 0 | E39: =D39 -> 0 | F39: =E39 -> 0 | G39: =F39 -> 0 | H39: - | I39: 0
A40: Verzinsung von Nachrangkapital | D40: 0.1 | E40: =D40 -> 0.1 | F40: =E40 -> 0.1 | G40: =F40 -> 0.1 | H40: =G40 -> 0.1 | I40: =H40 -> 0.1 | K40: Grundsätzliche Annahme
A42: Annahmen zur Finanzierungsstruktur
A43: Durchschnittliche Laufzeit von langfr. Fremdkapital in Jahren | D43: 8 | E43: 8 | F43: 8 | G43: 8 | H43: 8 | I43: 8
A44: Aufnahme von langfr. Bankverbindlichkeiten | D44: 460 | E44: 335 | F44: 330 | G44: 335 | H44: 335 | I44: 335 | K44: Analog Empfehlung
A45: Vorgesehene Rückzahlzahlungen von langfr. Bankverbindlichkeiten | D45: =-'Debt schedule'!C9/D43 -> -422.8125 | E45: =-'Debt schedule'!D9/E43 -> -427.46094 | F45: =-'Debt schedule'!E9/F43 -> -415.90332 | G45: =-'Debt schedule'!F9/G43 -> -405.16541 | H45: =-'Debt schedule'!G9/H43 -> -396.39473 | I45: =-'Debt schedule'!H9/I43 -> -388.72039 | K45: Leitet sich durch die FK-Struktur ab
...

Sheet GuV
A1: =Controls!A1 -> Forecast: Kundennamen
A2: {=MID(CELL("dateiname",A1),SEARCH("]",CELL("dateiname",A1))+1,31)} -> GuV
A3: (TEUR) | B3: =Controls!B7 -> 45291 | C3: =DATE(YEAR(B3)+1,MONTH(B3),DAY(B3)) -> 45657 | D3: =DATE(YEAR(C3)+1,MONTH(C3),DAY(C3)) -> 46022 | E3: =DATE(YEAR(D3)+1,MONTH(D3),DAY(D3)) -> 46387 | F3: =DATE(YEAR(E3)+1,MONTH(E3),DAY(E3)) -> 46752 | G3: =DATE(YEAR(F3)+1,MONTH(F3),DAY(F3)) -> 47118 | H3: =DATE(YEAR(G3)+1,MONTH(G3),DAY(G3)) -> 47483 | I3: =DATE(YEAR(H3)+1,MONTH(H3),DAY(H3)) -> 47848
A5: Umsatzerlöse | B5: ='Input (agree Daten)'!C238 -> 3574 | C5: ='Input (agree Daten)'!E238 -> 4301.3
A6: Bestandsveränderungen | B6: ='Input (agree Daten)'!C239+'Input (agree Daten)'!C240 -> 411.1 | C6: ='Input (agree Daten)'!E239+'Input (agree Daten)'!E240 -> -86.4
A7: Gesamtleistung | B7: =SUM(B5:B6) -> 3985.1 | C7: =SUM(C5:C6) -> 4214.9 | D7: =(1+'Input (Annahmen)'!D6)*GuV!C7 -> 4425.645 | E7: =(1+'Input (Annahmen)'!E6)*GuV!D7 -> 4646.9273 | F7: =(1+'Input (Annahmen)'!F6)*GuV!E7 -> 4879.2736 | G7: =(1+'Input (Annahmen)'!G6)*GuV!F7 -> 5123.2373 | H7: =(1+'Input (Annahmen)'!H6)*GuV!G7 -> 5379.3992 | I7: =(1+'Input (Annahmen)'!I6)*GuV!H7 -> 5648.3691
A8: Materialaufwand | B8: =-'Input (agree Daten)'!C245 -> -1259.3 | C8: =-'Input (agree Daten)'!E245 -> -1062.9 | D8: =D7*'Input (Annahmen)'!D7 -> -1327.6935 | E8: =E7*'Input (Annahmen)'!E7 -> -1347.6089 | F8: =F7*'Input (Annahmen)'!F7 -> -1414.9893 | G8: =G7*'Input (Annahmen)'!G7 -> -1485.7388 | H8: =H7*'Input (Annahmen)'!H7 -> -1560.0258 | I8: =I7*'Input (Annahmen)'!I7 -> -1638.027
A9: Rohertrag (Gross Profit) | B9: =SUM(B7:B8) -> 2725.8 | C9: =SUM(C7:C8) -> 3152 | D9: =SUM(D5:D8) -> 3097.9515 | E9: =SUM(E5:E8) -> 3299.3183 | F9: =SUM(F5:F8) -> 3464.2843 | G9: =SUM(G5:G8) -> 3637.4985 | H9: =SUM(H5:H8) -> 3819.3734 | I9: =SUM(I5:I8) -> 4010.3421
A11: Personalaufwand | B11: =-'Input (agree Daten)'!C260 -> -1214.2 | C11: =-'Input (agree Daten)'!E260 -> -1422.2 | D11: ='Input (Annahmen)'!D8*D7 -> -1416.2064 | E11: ='Input (Annahmen)'!E8*E7 -> -1487.0167 | F11: ='Input (Annahmen)'!F8*F7 -> -1561.3676 | G11: ='Input (Annahmen)'!G8*G7 -> -1639.4359 | H11: ='Input (Annahmen)'!H8*H7 -> -1721.4077 | I11: ='Input (Annahmen)'!I8*I7 -> -1807.4781
A12: Raumkosten | B12: =-'Input (agree Daten)'!C268 -> 0 | C12: =-'Input (agree Daten)'!E268 -> 0 | D12: ='Input (Annahmen)'!D9*GuV!D7 -> -61.95903 | E12: ='Input (Annahmen)'!E9*GuV!E7 -> -65.056982 | F12: ='Input (Annahmen)'!F9*GuV!F7 -> -68.309831 | G12: ='Input (Annahmen)'!G9*GuV!G7 -> -71.725322 | H12: ='Input (Annahmen)'!H9*GuV!H7 -> -75.311588 | I12: ='Input (Annahmen)'!I9*GuV!I7 -> -79.077168
A13: Versicherungen und Beiträge | B13: =-'Input (agree Daten)'!C270 -> 0 | C13: =-'Input (agree Daten)'!E270 -> 0 | D13: ='Input (Annahmen)'!D10*GuV!D7 -> -57.533385 | E13: ='Input (Annahmen)'!E10*GuV!E7 -> -60.410054 | F13: ='Input (Annahmen)'!F10*GuV!F7 -> -63.430557 | G13: ='Input (Annahmen)'!G10*GuV!G7 -> -66.602085 | H13: ='Input (Annahmen)'!H10*GuV!H7 -> -69.932189 | I13: ='Input (Annahmen)'!I10*GuV!I7 -> -73.428799
A14: Reperatur und Instanthaltung | B14: =-'Input (agree Daten)'!C275 -> 0 | C14: =-'Input (agree Daten)'!E275 -> 0 | D14: ='Input (Annahmen)'!D11*GuV!D7 -> -143.83346 | E14: ='Input (Annahmen)'!E11*GuV!E7 -> -151.02514 | F14: ='Input (Annahmen)'!F11*GuV!F7 -> -158.57639 | G14: ='Input (Annahmen)'!G11*GuV!G7 -> -166.50521 | H14: ='Input (Annahmen)'!H11*GuV!H7 -> -174.83047 | I14: ='Input (Annahmen)'!I11*GuV!I7 -> -183.572
A15: Fahrzeugkosten | B15: =-'Input (agree Daten)'!C272 -> 0 | C15: =-'Input (agree Daten)'!E272 -> 0 | D15: ='Input (Annahmen)'!D12*GuV!D7 -> -429.28757 | E15: ='Input (Annahmen)'!E12*GuV!E7 -> -450.75194 | F15: ='Input (Annahmen)'!F12*GuV!F7 -> -473.28954 | G15: ='Input (Annahmen)'!G12*GuV!G7 -> -496.95402 | H15: ='Input (Annahmen)'!H12*GuV!H7 -> -521.80172 | I15: ='Input (Annahmen)'!I12*GuV!I7 -> -547.8918
A16: Werbe- und Reisekosten | B16: =-'Input (agree Daten)'!C273 -> 0 | C16: =-'Input (agree Daten)'!E273 -> 0 | D16: ='Input (Annahmen)'!D13*GuV!D7 -> -35.40516 | E16: ='Input (Annahmen)'!E13*GuV!E7 -> -37.175418 | F16: ='Input (Annahmen)'!F13*GuV!F7 -> -39.034189 | G16: ='Input (Annahmen)'!G13*GuV!G7 -> -40.985898 | H16: ='Input (Annahmen)'!H13*GuV!H7 -> -43.035193 | I16: ='Input (Annahmen)'!I13*GuV!I7 -> -45.186953
A17: Verschiedene betr. Kosten | B17: ='Input (agree Daten)'!C254-('Input (agree Daten)'!C265+'Input (agree Daten)'!C267+'Input (agree Daten)'!C278+'Input (agree Daten)'!C279-'Input (agree Daten)'!C268-'Input (agree Daten)'!C270-'Input (agree Daten)'!C272-'Input (agree Daten)'!C273-'Input (agree Daten)'!C275) -> -919.2 | C17: ='Input (agree Daten)'!E254-('Input (agree Daten)'!E265+'Input (agree Daten)'!E267+'Input (agree Daten)'!E278+'Input (agree Daten)'!E279-'Input (agree Daten)'!E268-'Input (agree Daten)'!E270-'Input (agree Daten)'!E272-'Input (agree Daten)'!E273-'Input (agree Daten)'!E275) -> -1043.9 | D17: ='Input (Annahmen)'!D14*GuV!D7 -> -243.41048 | E17: ='Input (Annahmen)'!E14*GuV!E7 -> -255.581 | F17: ='Input (Annahmen)'!F14*GuV!F7 -> -268.36005 | G17: ='Input (Annahmen)'!G14*GuV!G7 -> -281.77805 | H17: ='Input (Annahmen)'!H14*GuV!H7 -> -295.86695 | I17: ='Input (Annahmen)'!I14*GuV!I7 -> -310.6603
A18: Abschreibungen | B18: =-'Input (agree Daten)'!C264 -> -459.4 | C18: =-'Input (agree Daten)'!E264 -> -431.7 | D18: ='Side Calcs'!D8+'Side Calcs'!D14 -> -458.73678 | E18: ='Side Calcs'!E8+'Side Calcs'!E14 -> -445.29311 | F18: ='Side Calcs'!F8+'Side Calcs'!F14 -> -434.69645 | G18: ='Side Calcs'!G8+'Side Calcs'!G14 -> -426.4918 | H18: ='Side Calcs'!H8+'Side Calcs'!H14 -> -420.20351 | I18: ='Side Calcs'!I8+'Side Calcs'!I14 -> -415.31234
A19: Betriebsergebnis (EBIT) | B19: =SUM(B9:B18) -> 133 | C19: =SUM(C9:C18) -> 254.2 | D19: =SUM(D9:D18) -> 251.57924 | E19: =SUM(E9:E18) -> 347.00799 | F19: =SUM(F9:F18) -> 397.2197 | G19: =SUM(G9:G18) -> 447.02015 | H19: =SUM(H9:H18) -> 496.98405 | I19: =SUM(I9:I18) -> 547.73459
A21: Zinseinnahmen | B21: ='Input (agree Daten)'!C282 -> 0 | C21: ='Input (agree Daten)'!E282 -> 0 | D21: =IF(Controls!$B$6=1,'Debt schedule'!D58, 0) -> 0 | E21: =IF(Controls!$B$6=1,'Debt schedule'!E58, 0) -> 0 | F21: =IF(Controls!$B$6=1,'Debt schedule'!F58, 0) -> 0 | G21: =IF(Controls!$B$6=1,'Debt schedule'!G58, 0) -> 0 | H21: =IF(Controls!$B$6=1,'Debt schedule'!H58, 0) -> 0 | I21: =IF(Controls!$B$6=1,'Debt schedule'!I58, 0) -> 0
A22: Zinskosten | B22: =-('Input (agree Daten)'!C284+'Input (agree Daten)'!C286) -> -105 | C22: =-('Input (agree Daten)'!E284+'Input (agree Daten)'!E286) -> -102.9 | D22: =IF(Controls!$B$6=1,SUM('Debt schedule'!D59, 'Debt schedule'!D60), 0) -> -123.89153 | E22: =IF(Controls!$B$6=1,SUM('Debt schedule'!E59, 'Debt schedule'!E60), 0) -> -136.37464 | F22: =IF(Controls!$B$6=1,SUM('Debt schedule'!F59, 'Debt schedule'!F60), 0) -> -141.241 | G22: =IF(Controls!$B$6=1,SUM('Debt schedule'!G59, 'Debt schedule'!G60), 0) -> -170.18203 | H22: =IF(Controls!$B$6=1,SUM('Debt schedule'!H59, 'Debt schedule'!H60), 0) -> -166.89302 | I22: =IF(Controls!$B$6=1,SUM('Debt schedule'!I59, 'Debt schedule'!I60), 0) -> -164.01515
A23: Finanzergebnis | B23: =SUM(B21:B22) -> -105 | C23: =SUM(C21:C22) -> -102.9 | D23: =SUM(D21:D22) -> -123.89153 | E23: =SUM(E21:E22) -> -136.37464 | F23: =SUM(F21:F22) -> -141.241 | G23: =SUM(G21:G22) -> -170.18203 | H23: =SUM(H21:H22) -> -166.89302 | I23: =SUM(I21:I22) -> -164.01515
A25: Betriebsergebnis vor Steuer (EBT) | B25: =SUM(B19,B23) -> 28 | C25: =SUM(C19,C23) -> 151.3 | D25: =SUM(D19,D23) -> 127.68771 | E25: =SUM(E19,E23) -> 210.63335 | F25: =SUM(F19,F23) -> 255.9787 | G25: =SUM(G19,G23) -> 276.83813 | H25: =SUM(H19,H23) -> 330.09103 | I25: =SUM(I19,I23) -> 383.71944
A27: Steuern | B27: =-'Input (agree Daten)'!C331 -> -4.2 | C27: =-'Input (agree Daten)'!E331 -> -7.7 | D27: =D25*'Input (Annahmen)'!D15 -> -33.326493 | E27: =E25*'Input (Annahmen)'!E15 -> -63.190005 | F27: =F25*'Input (Annahmen)'!F15 -> -89.592546 | G27: =G25*'Input (Annahmen)'!G15 -> -96.893345 | H27: =H25*'Input (Annahmen)'!H15 -> -122.13368 | I27: =I25*'Input (Annahmen)'!I15 -> -141.97619
A28: Betriebsergebnis nach Steuern (Net income) | B28: =SUM(B25:B27) -> 23.8 | C28: =SUM(C25:C27) -> 143.6 | D28: =SUM(D25:D27) -> 94.361219 | E28: =SUM(E25:E27) -> 147.44335 | F28: =SUM(F25:F27) -> 166.38616 | G28: =SUM(G25:G27) -> 179.94478 | H28: =SUM(H25:H27) -> 207.95735 | I28: =SUM(I25:I27) -> 241.74325
A30: Überschuss für Thesaurierung und Ausschüttung | B30: =B28 -> 23.8 | C30: =C28 -> 143.6 | D30: =D28 -> 94.361219 | E30: =E28 -> 147.44335 | F30: =F28 -> 166.38616 | G30: =G28 -> 179.94478 | H30: =H28 -> 207.95735 | I30: =I28 -> 241.74325
A32: EBITDA | B32: =B19-B18 -> 592.4 | C32: =C19-C18 -> 685.9 | D32: =D19-D18 -> 710.31602 | E32: =E19-E18 -> 792.3011 | F32: =F19-F18 -> 831.91615 | G32: =G19-G18 -> 873.51196 | H32: =H19-H18 -> 917.18756 | I32: =I19-I18 -> 963.04693

Sheet Bilanz
A1: =Controls!A1 -> Forecast: Kundennamen
A2: {=MID(CELL("dateiname",A1),SEARCH("]",CELL("dateiname",A1))+1,31)} -> Bilanz
A3: (TEUR) | B3: =Controls!B7 -> 45291 | C3: =DATE(YEAR(B3)+1,MONTH(B3),DAY(B3)) -> 45657 | D3: =DATE(YEAR(C3)+1,MONTH(C3),DAY(C3)) -> 46022 | E3: =DATE(YEAR(D3)+1,MONTH(D3),DAY(D3)) -> 46387 | F3: =DATE(YEAR(E3)+1,MONTH(E3),DAY(E3)) -> 46752 | G3: =DATE(YEAR(F3)+1,MONTH(F3),DAY(F3)) -> 47118 | H3: =DATE(YEAR(G3)+1,MONTH(G3),DAY(G3)) -> 47483 | I3: =DATE(YEAR(H3)+1,MONTH(H3),DAY(H3)) -> 47848
A5: AKTIVA (assets)
A7: Immaterielle Vermögenswerte | B7: ='Input (agree Daten)'!C64 -> 2.8 | C7: ='Input (agree Daten)'!E64 -> 4.2 | D7: ='Side Calcs'!D9 -> 8.526 | E7: ='Side Calcs'!E9 -> 14.42658 | F7: ='Side Calcs'!F9 -> 22.428701 | G7: ='Side Calcs'!G9 -> 33.23359 | H7: ='Side Calcs'!H9 -> 47.774264 | I7: ='Side Calcs'!I9 -> 67.292038
A8: Sachanlagevermögen | B8: =SUM('Input (agree Daten)'!C65:C68) -> 3810.8 | C8: =SUM('Input (agree Daten)'!E65:E68) -> 4061.7 | D8: ='Side Calcs'!D15 -> 3955.6288 | E8: ='Side Calcs'!E15 -> 3879.2763 | F8: ='Side Calcs'!F15 -> 3830.161 | G8: ='Side Calcs'!G15 -> 3806.1267 | H8: ='Side Calcs'!H15 -> 3805.308 | I8: ='Side Calcs'!I15 -> 3826.0997
A9: Sonstige Anlagegüter | B9: =SUM('Input (agree Daten)'!C71:C78) -> 0 | C9: =SUM('Input (agree Daten)'!E71:E78) -> 0 | D9: ='Input (Annahmen)'!D20 -> 0 | E9: ='Input (Annahmen)'!E20 -> 0 | F9: ='Input (Annahmen)'!F20 -> 0 | G9: ='Input (Annahmen)'!G20 -> 0 | H9: ='Input (Annahmen)'!H20 -> 0 | I9: ='Input (Annahmen)'!I20 -> 0
A10: Anlagevermögen | B10: =SUM(B7:B9) -> 3813.6 | C10: =SUM(C7:C9) -> 4065.9 | D10: =SUM(D7:D9) -> 3964.1548 | E10: =SUM(E7:E9) -> 3893.7029 | F10: =SUM(F7:F9) -> 3852.5897 | G10: =SUM(G7:G9) -> 3839.3603 | H10: =SUM(H7:H9) -> 3853.0823 | I10: =SUM(I7:I9) -> 3893.3917
A12: Vorräte | B12: ='Input (agree Daten)'!C82+'Input (agree Daten)'!C83-'Input (agree Daten)'!C84+'Input (agree Daten)'!C86+'Input (agree Daten)'!C87+'Input (agree Daten)'!C88 -> 41 | C12: ='Input (agree Daten)'!E82+'Input (agree Daten)'!E83-'Input (agree Daten)'!E84+'Input (agree Daten)'!E86+'Input (agree Daten)'!E87+'Input (agree Daten)'!E88 -> 105.7 | D12: ='Side Calcs'!D18 -> 45.832707 | E12: ='Side Calcs'!E18 -> 46.520198 | F12: ='Side Calcs'!F18 -> 48.846208 | G12: ='Side Calcs'!G18 -> 51.288518 | H12: ='Side Calcs'!H18 -> 53.852944 | I12: ='Side Calcs'!I18 -> 56.545591
A13: Forderungen aus L+L | B13: ='Input (agree Daten)'!C90 -> 834.2 | C13: ='Input (agree Daten)'!E90 -> 546.9 | D13: ='Side Calcs'!D21 -> 1091.2549 | E13: ='Side Calcs'!E21 -> 1145.8177 | F13: ='Side Calcs'!F21 -> 1203.1086 | G13: ='Side Calcs'!G21 -> 1263.264 | H13: ='Side Calcs'!H21 -> 1326.4272 | I13: ='Side Calcs'!I21 -> 1392.7485
A14: Sonstiges Umlaufvermögen | B14: =SUM('Input (agree Daten)'!C91:C95,'Input (agree Daten)'!C97:C99,'Input (agree Daten)'!C108,'Input (agree Daten)'!C109,'Input (agree Daten)'!C111) -> 46.6 | C14: =SUM('Input (agree Daten)'!E91:E95,'Input (agree Daten)'!E97:E99,'Input (agree Daten)'!E108,'Input (agree Daten)'!E109,'Input (agree Daten)'!E111) -> 115.9 | D14: ='Input (Annahmen)'!D21 -> 115.9 | E14: ='Input (Annahmen)'!E21 -> 115.9 | F14: ='Input (Annahmen)'!F21 -> 115.9 | G14: ='Input (Annahmen)'!G21 -> 115.9 | H14: ='Input (Annahmen)'!H21 -> 115.9 | I14: ='Input (Annahmen)'!I21 -> 115.9
A15: (Nicht) notwendige Liquidität | B15: 0 | C15: 0 | D15: =MAX(0,CashflowStatement!D40) -> 98.409308 | E15: =MAX(0,CashflowStatement!E40) -> 126.66417 | F15: =MAX(0,CashflowStatement!F40) -> 148.43701 | G15: =MAX(0,CashflowStatement!G40) -> 166.63143 | H15: =MAX(0,CashflowStatement!H40) -> 189.41695 | I15: =MAX(0,CashflowStatement!I40) -> 221.57252
A16: Kassenbestand / Kontoguthaben (cash) | B16: ='Input (agree Daten)'!C101+'Input (agree Daten)'!C102 -> 26.4 | C16: ='Input (agree Daten)'!E101+'Input (agree Daten)'!E102 -> 34.5 | D16: ='Input (Annahmen)'!D22*GuV!D7 -> 48.682095 | E16: ='Input (Annahmen)'!E22*GuV!E7 -> 51.1162 | F16: ='Input (Annahmen)'!F22*GuV!F7 -> 53.67201 | G16: ='Input (Annahmen)'!G22*GuV!G7 -> 56.35561 | H16: ='Input (Annahmen)'!H22*GuV!H7 -> 59.173391 | I16: ='Input (Annahmen)'!I22*GuV!I7 -> 62.13206
A17: Umlaufvermögen | B17: =SUM(B12:B16) -> 948.2 | C17: =SUM(C12:C16) -> 803 | D17: =SUM(D12:D16) -> 1400.079 | E17: =SUM(E12:E16) -> 1486.0182 | F17: =SUM(F12:F16) -> 1569.9638 | G17: =SUM(G12:G16) -> 1653.4395 | H17: =SUM(H12:H16) -> 1744.7705 | I17: =SUM(I12:I16) -> 1848.8987
A19: Bilanzsumme | B19: =SUM(B10,B17) -> 4761.8 | C19: =SUM(C10,C17) -> 4868.9 | D19: =SUM(D10,D17) -> 5364.2339 | E19: =SUM(E10,E17) -> 5379.7211 | F19: =SUM(F10,F17) -> 5422.5535 | G19: =SUM(G10,G17) -> 5492.7998 | H19: =SUM(H10,H17) -> 5597.8528 | I19: =SUM(I10,I17) -> 5742.2905
A22: PASSIVA
A24: Stammkapital / gez. Kapital | B24: ='Input (agree Daten)'!C127 -> -20.3 | C24: ='Input (agree Daten)'!E127 -> -41.8 | D24: ='Input (Annahmen)'!D23 -> -41.8 | E24: ='Input (Annahmen)'!E23 -> -41.8 | F24: ='Input (Annahmen)'!F23 -> -41.8 | G24: ='Input (Annahmen)'!G23 -> -41.8 | H24: ='Input (Annahmen)'!H23 -> -41.8 | I24: ='Input (Annahmen)'!I23 -> -41.8
A25: Rücklagen | B25: ='Input (agree Daten)'!C134+'Input (agree Daten)'!C135 -> 91.3 | C25: ='Input (agree Daten)'!E134+'Input (agree Daten)'!E135 -> 91.3 | D25: ='Input (Annahmen)'!D24 -> 91.3 | E25: ='Input (Annahmen)'!E24 -> 91.3 | F25: ='Input (Annahmen)'!F24 -> 91.3 | G25: ='Input (Annahmen)'!G24 -> 91.3 | H25: ='Input (Annahmen)'!H24 -> 91.3 | I25: ='Input (Annahmen)'!I24 -> 91.3
A26: Bilanzgewinn (Verlust) | B26: =SUM('Input (agree Daten)'!C137:C144) -> 51 | C26: =SUM('Input (agree Daten)'!E137:E144) -> 91.8 | D26: ='Side Calcs'!D33 -> 111.16122 | E26: ='Side Calcs'!E33 -> 179.85456 | F26: ='Side Calcs'!F33 -> 263.55322 | G26: ='Side Calcs'!G33 -> 356.67613 | H26: ='Side Calcs'!H33 -> 473.47051 | I26: ='Side Calcs'!I33 -> 619.49264
A27: Eigenkapital | B27: =SUM(B24:B26) -> 122 | C27: =SUM(C24:C26) -> 141.3 | D27: =SUM(D24:D26) -> 160.66122 | E27: =SUM(E24:E26) -> 229.35456 | F27: =SUM(F24:F26) -> 313.05322 | G27: =SUM(G24:G26) -> 406.17613 | H27: =SUM(H24:H26) -> 522.97051 | I27: =SUM(I24:I26) -> 668.99264
A29: Nachrangkapital | B29: =-'Input (agree Daten)'!C158+SUM('Input (agree Daten)'!C159:C163) -> -26.1 | C29: =-'Input (agree Daten)'!E158+SUM('Input (agree Daten)'!E159:E163) -> -41.3 | D29: ='Side Calcs'!D40 -> 98.7 | E29: ='Side Calcs'!E40 -> 98.7 | F29: ='Side Calcs'!F40 -> 98.7 | G29: ='Side Calcs'!G40 -> 98.7 | H29: ='Side Calcs'!H40 -> 98.7 | I29: ='Side Calcs'!I40 -> 98.7
A30: Eigen- und eigenkapitalähnliches Kapital | B30: =SUM(B27:B29) -> 95.9 | C30: =SUM(C27:C29) -> 100 | D30: =SUM(D27:D29) -> 259.36122 | E30: =SUM(E27:E29) -> 328.05456 | F30: =SUM(F27:F29) -> 411.75322 | G30: =SUM(G27:G29) -> 504.87613 | H30: =SUM(H27:H29) -> 621.67051 | I30: =SUM(I27:I29) -> 767.69264
A32: Pensionsrückstellungen | B32: ='Input (agree Daten)'!C166 -> 0 | C32: ='Input (agree Daten)'!E166 -> 0 | D32: ='Input (Annahmen)'!D25*GuV!D7 -> 0 | E32: ='Input (Annahmen)'!E25*GuV!E7 -> 0 | F32: ='Input (Annahmen)'!F25*GuV!F7 -> 0 | G32: ='Input (Annahmen)'!G25*GuV!G7 -> 0 | H32: ='Input (Annahmen)'!H25*GuV!H7 -> 0 | I32: ='Input (Annahmen)'!I25*GuV!I7 -> 0
A33: Langfristige Bankverbindlichkeiten | B33: ='Input (agree Daten)'!C171 -> 3414.5 | C33: ='Input (agree Daten)'!E171 -> 3382.5 | D33: ='Debt schedule'!D9 -> 3419.6875 | E33: ='Debt schedule'!E9 -> 3327.2266 | F33: ='Debt schedule'!F9 -> 3241.3232 | G33: ='Debt schedule'!G9 -> 3171.1578 | H33: ='Debt schedule'!H9 -> 3109.7631 | I33: ='Debt schedule'!I9 -> 3056.0427
A34: Andere langfr. Verbindlichkeiten | B34: =SUM('Input (agree Daten)'!C167:C168,'Input (agree Daten)'!C170,'Input (agree Daten)'!C173:C177,'Input (agree Daten)'!C179:C185,'Input (agree Daten)'!C218) -> 327.4 | C34: =SUM('Input (agree Daten)'!E167:E168,'Input (agree Daten)'!E170,'Input (agree Daten)'!E173:E177,'Input (agree Daten)'!E179:E185,'Input (agree Daten)'!E218) -> 823.7 | D34: ='Input (Annahmen)'!D26 -> 823.7 | E34: ='Input (Annahmen)'!E26 -> 823.7 | F34: ='Input (Annahmen)'!F26 -> 823.7 | G34: ='Input (Annahmen)'!G26 -> 823.7 | H34: ='Input (Annahmen)'!H26 -> 823.7 | I34: ='Input (Annahmen)'!I26 -> 823.7
A35: Langfristiges Fremdkapital | B35: =SUM(B32:B34) -> 3741.9 | C35: =SUM(C32:C34) -> 4206.2 | D35: =SUM(D32:D34) -> 4243.3875 | E35: =SUM(E32:E34) -> 4150.9266 | F35: =SUM(F32:F34) -> 4065.0232 | G35: =SUM(G32:G34) -> 3994.8578 | H35: =SUM(H32:H34) -> 3933.4631 | I35: =SUM(I32:I34) -> 3879.7427
A37: Lieferantenverbindlichkeiten | B37: ='Input (agree Daten)'!C205+'Input (agree Daten)'!C206 -> 287.6 | C37: ='Input (agree Daten)'!E205+'Input (agree Daten)'!E206 -> 214.4 | D37: ='Side Calcs'!D24 -> 109.12549 | E37: ='Side Calcs'!E24 -> 110.76238 | F37: ='Side Calcs'!F24 -> 116.30049 | G37: ='Side Calcs'!G24 -> 122.11552 | H37: ='Side Calcs'!H24 -> 128.22129 | I37: ='Side Calcs'!I24 -> 134.63236
A38: Kurzfristige Bankverbindlichkeiten | B38: ='Input (agree Daten)'!C196 -> 259.9 | C38: ='Input (agree Daten)'!E196 -> 69.9 | D38: ='Debt schedule'!D19 -> 0 | E38: ='Debt schedule'!E19 -> 0 | F38: ='Debt schedule'!F19 -> 0 | G38: ='Debt schedule'!G19 -> 0 | H38: ='Debt schedule'!H19 -> 0 | I38: ='Debt schedule'!I19 -> 0
A39: Liquiditätsunterdeckung / Revolver | D39: =-MIN(0,CashflowStatement!D40) -> 0 | E39: =-MIN(0,CashflowStatement!E40) -> 0 | F39: =-MIN(0,CashflowStatement!F40) -> 0 | G39: =-MIN(0,CashflowStatement!G40) -> 0 | H39: =-MIN(0,CashflowStatement!H40) -> 0 | I39: =-MIN(0,CashflowStatement!I40) -> 0
A40: Andere kurzfr. Verbindlichkeiten | B40: ='Input (agree Daten)'!C191+'Input (agree Daten)'!C192+'Input (agree Daten)'!C193+SUM('Input (agree Daten)'!C195,'Input (agree Daten)'!C198:C202,'Input (agree Daten)'!C207:C211,'Input (agree Daten)'!C213,'Input (agree Daten)'!C216) -> 376.5 | C40: ='Input (agree Daten)'!E191+'Input (agree Daten)'!E192+'Input (agree Daten)'!E193+SUM('Input (agree Daten)'!E195,'Input (agree Daten)'!E198:E202,'Input (agree Daten)'!E207:E211,'Input (agree Daten)'!E213,'Input (agree Daten)'!E216) -> 278.4 | D40: ='Input (Annahmen)'!D27 -> 752.35965 | E40: ='Input (Annahmen)'!E27 -> 789.97763 | F40: ='Input (Annahmen)'!F27 -> 829.47651 | G40: ='Input (Annahmen)'!G27 -> 870.95034 | H40: ='Input (Annahmen)'!H27 -> 914.49786 | I40: ='Input (Annahmen)'!I27 -> 960.22275
A41: Kurzfristiges Fremdkapital | B41: =SUM(B37:B40) -> 924 | C41: =SUM(C37:C40) -> 562.7 | D41: =SUM(D37:D40) -> 861.48514 | E41: =SUM(E37:E40) -> 900.74001 | F41: =SUM(F37:F40) -> 945.77701 | G41: =SUM(G37:G40) -> 993.06586 | H41: =SUM(H37:H40) -> 1042.7192 | I41: =SUM(I37:I40) -> 1094.8551
A43: Bilanzsumme | B43: =SUM(B30,B35,B41) -> 4761.8 | C43: =SUM(C30,C35,C41) -> 4868.9 | D43: =SUM(D30,D35,D41) -> 5364.2339 | E43: =SUM(E30,E35,E41) -> 5379.7211 | F43: =SUM(F30,F35,F41) -> 5422.5535 | G43: =SUM(G30,G35,G41) -> 5492.7998 | H43: =SUM(H30,H35,H41) -> 5597.8528 | I43: =SUM(I30,I35,I41) -> 5742.2905
A45: Check | B45: =IF(ROUND(B19-B43,5)=0,"OK",B19-B43) -> OK | C45: =IF(ROUND(C19-C43,5)=0,"OK",C19-C43) -> OK | D45: =IF(ROUND(D19-D43,5)=0,"OK",D19-D43) -> OK | E45: =IF(ROUND(E19-E43,5)=0,"OK",E19-E43) -> OK | F45: =IF(ROUND(F19-F43,5)=0,"OK",F19-F43) -> OK | G45: =IF(ROUND(G19-G43,5)=0,"OK",G19-G43) -> OK | H45: =IF(ROUND(H19-H43,5)=0,"OK",H19-H43) -> OK | I45: =IF(ROUND(I19-I43,5)=0,"OK",I19-I43) -> OK

Sheet CashflowStatement
A1: =Controls!A1 -> Forecast: Kundennamen
A2: {=MID(CELL("dateiname",A1),SEARCH("]",CELL("dateiname",A1))+1,31)} -> CashflowStatement
A3: (TEUR) | B3: =Controls!B7 -> 45291 | C3: =DATE(YEAR(B3)+1,MONTH(B3),DAY(B3)) -> 45657 | D3: =DATE(YEAR(C3)+1,MONTH(C3),DAY(C3)) -> 46022 | E3: =DATE(YEAR(D3)+1,MONTH(D3),DAY(D3)) -> 46387 | F3: =DATE(YEAR(E3)+1,MONTH(E3),DAY(E3)) -> 46752 | G3: =DATE(YEAR(F3)+1,MONTH(F3),DAY(F3)) -> 47118 | H3: =DATE(YEAR(G3)+1,MONTH(G3),DAY(G3)) -> 47483 | I3: =DATE(YEAR(H3)+1,MONTH(H3),DAY(H3)) -> 47848
A5: 1) Operating Cashflow
A6: =GuV!A28 -> Betriebsergebnis nach Steuern (Net income) | D6: =GuV!D28 -> 94.361219 | E6: =GuV!E28 -> 147.44335 | F6: =GuV!F28 -> 166.38616 | G6: =GuV!G28 -> 179.94478 | H6: =GuV!H28 -> 207.95735 | I6: =GuV!I28 -> 241.74325
A7: Abschreibungen auf immat. Vermögensg. | D7: =-'Side Calcs'!D8 -> -1.386 | E7: =-'Side Calcs'!E8 -> -2.81358 | F7: =-'Side Calcs'!F8 -> -4.7607714 | G7: =-'Side Calcs'!G8 -> -7.4014715 | H7: =-'Side Calcs'!H8 -> -10.967085 | I7: =-'Side Calcs'!I8 -> -15.765507
A8: Abschreibungen auf das Sachanlagevermögen | D8: =-'Side Calcs'!D14 -> 460.12278 | E8: =-'Side Calcs'!E14 -> 448.10669 | F8: =-'Side Calcs'!F14 -> 439.45722 | G8: =-'Side Calcs'!G14 -> 433.89328 | H8: =-'Side Calcs'!H14 -> 431.17059 | I8: =-'Side Calcs'!I14 -> 431.07785
A9: Veränderungen im weiteren Anlagevermögen | D9: =Bilanz!C9-Bilanz!D9 -> 0 | E9: =Bilanz!D9-Bilanz!E9 -> 0 | F9: =Bilanz!E9-Bilanz!F9 -> 0 | G9: =Bilanz!F9-Bilanz!G9 -> 0 | H9: =Bilanz!G9-Bilanz!H9 -> 0 | I9: =Bilanz!H9-Bilanz!I9 -> 0
A10: Bestandsveränderungen der Vorräte | D10: =Bilanz!C12-Bilanz!D12 -> 59.867293 | E10: =Bilanz!D12-Bilanz!E12 -> -0.68749061 | F10: =Bilanz!E12-Bilanz!F12 -> -2.3260099 | G10: =Bilanz!F12-Bilanz!G12 -> -2.4423104 | H10: =Bilanz!G12-Bilanz!H12 -> -2.5644259 | I10: =Bilanz!H12-Bilanz!I12 -> -2.6926472
A11: Bestandsveränderung der Kundenforderungen | D11: =Bilanz!C13-Bilanz!D13 -> -544.35493 | E11: =Bilanz!D13-Bilanz!E13 -> -54.562747 | F11: =Bilanz!E13-Bilanz!F13 -> -57.290884 | G11: =Bilanz!F13-Bilanz!G13 -> -60.155428 | H11: =Bilanz!G13-Bilanz!H13 -> -63.1632 | I11: =Bilanz!H13-Bilanz!I13 -> -66.321359
A12: Bestandsveränderungen bei dem sonst. Umlaufvermögen | D12: =Bilanz!C14-Bilanz!D14 -> 0 | E12: =Bilanz!D14-Bilanz!E14 -> 0 | F12: =Bilanz!E14-Bilanz!F14 -> 0 | G12: =Bilanz!F14-Bilanz!G14 -> 0 | H12: =Bilanz!G14-Bilanz!H14 -> 0 | I12: =Bilanz!H14-Bilanz!I14 -> 0
A13: Bestandsveränderungen bei den Cashbeständen | D13: =Bilanz!C16-Bilanz!D16 -> -14.182095 | E13: =Bilanz!D16-Bilanz!E16 -> -2.4341048 | F13: =Bilanz!E16-Bilanz!F16 -> -2.55581 | G13: =Bilanz!F16-Bilanz!G16 -> -2.6836005 | H13: =Bilanz!G16-Bilanz!H16 -> -2.8177805 | I13: =Bilanz!H16-Bilanz!I16 -> -2.9586695
A14: Veränderung bei den Pensionsrückstellungen | D14: =Bilanz!D32-Bilanz!C32 -> 0 | E14: =Bilanz!E32-Bilanz!D32 -> 0 | F14: =Bilanz!F32-Bilanz!E32 -> 0 | G14: =Bilanz!G32-Bilanz!F32 -> 0 | H14: =Bilanz!H32-Bilanz!G32 -> 0 | I14: =Bilanz!I32-Bilanz!H32 -> 0
A15: Veränderungen bei den weiteren langfr. Verbindlichkeiten | D15: =Bilanz!D34-Bilanz!C34 -> 0 | E15: =Bilanz!E34-Bilanz!D34 -> 0 | F15: =Bilanz!F34-Bilanz!E34 -> 0 | G15: =Bilanz!G34-Bilanz!F34 -> 0 | H15: =Bilanz!H34-Bilanz!G34 -> 0 | I15: =Bilanz!I34-Bilanz!H34 -> 0
A16: Veränderungen bei den Lieferantenverbindlichkeiten | D16: =Bilanz!D37-Bilanz!C37 -> -105.27451 | E16: =Bilanz!E37-Bilanz!D37 -> 1.6368824 | F16: =Bilanz!F37-Bilanz!E37 -> 5.5381188 | G16: =Bilanz!G37-Bilanz!F37 -> 5.8150247 | H16: =Bilanz!H37-Bilanz!G37 -> 6.105776 | I16: =Bilanz!I37-Bilanz!H37 -> 6.4110647
A17: Veränderungen bei den anderen kurzfr. Verbindlichkeiten | D17: =Bilanz!D40-Bilanz!C40 -> 473.95965 | E17: =Bilanz!E40-Bilanz!D40 -> 37.617983 | F17: =Bilanz!F40-Bilanz!E40 -> 39.498882 | G17: =Bilanz!G40-Bilanz!F40 -> 41.473826 | H17: =Bilanz!H40-Bilanz!G40 -> 43.547517 | I17: =Bilanz!I40-Bilanz!H40 -> 45.724893
A18: Summe Operating Cashflow | D18: =SUM(D6:D17) -> 423.11341 | E18: =SUM(E6:E17) -> 574.30698 | F18: =SUM(F6:F17) -> 583.94691 | G18: =SUM(G6:G17) -> 588.4441 | H18: =SUM(H6:H17) -> 609.26874 | I18: =SUM(I6:I17) -> 637.21888
A20: 2) Investing Cashflow
A21: Ersatz- und Erweiterungsinvest. immat. Vermögensg. | D21: =-'Side Calcs'!D7 -> -2.94 | E21: =-'Side Calcs'!E7 -> -3.087 | F21: =-'Side Calcs'!F7 -> -3.24135 | G21: =-'Side Calcs'!G7 -> -3.4034175 | H21: =-'Side Calcs'!H7 -> -3.5735884 | I21: =-'Side Calcs'!I7 -> -3.7522678
A22: Ersatz- und Erweiterungsinvest. Sachanlagevermögen | D22: =-'Side Calcs'!D13 -> -354.0516 | E22: =-'Side Calcs'!E13 -> -371.75418 | F22: =-'Side Calcs'!F13 -> -390.34189 | G22: =-'Side Calcs'!G13 -> -409.85898 | H22: =-'Side Calcs'!H13 -> -430.35193 | I22: =-'Side Calcs'!I13 -> -451.86953
A23: Summe Investing Cashflow | D23: =SUM(D21:D22) -> -356.9916 | E23: =SUM(E21:E22) -> -374.84118 | F23: =SUM(F21:F22) -> -393.58324 | G23: =SUM(G21:G22) -> -413.2624 | H23: =SUM(H21:H22) -> -433.92552 | I23: =SUM(I21:I22) -> -455.6218
A25: 3) Financing Cashflow
A26: Veränderungen beim gez. Kapital / Stammkapital | D26: =Bilanz!D24-Bilanz!C24 -> 0 | E26: =Bilanz!E24-Bilanz!D24 -> 0 | F26: =Bilanz!F24-Bilanz!E24 -> 0 | G26: =Bilanz!G24-Bilanz!F24 -> 0 | H26: =Bilanz!H24-Bilanz!G24 -> 0 | I26: =Bilanz!I24-Bilanz!H24 -> 0
A27: Veränderungen bei den Rücklagen | D27: =Bilanz!D25-Bilanz!C25 -> 0 | E27: =Bilanz!E25-Bilanz!D25 -> 0 | F27: =Bilanz!F25-Bilanz!E25 -> 0 | G27: =Bilanz!G25-Bilanz!F25 -> 0 | H27: =Bilanz!H25-Bilanz!G25 -> 0 | I27: =Bilanz!I25-Bilanz!H25 -> 0
A28: Ausschüttungen (Privatentnahmen) | D28: ='Side Calcs'!D32 -> -75 | E28: ='Side Calcs'!E32 -> -78.75 | F28: ='Side Calcs'!F32 -> -82.6875 | G28: ='Side Calcs'!G32 -> -86.821875 | H28: ='Side Calcs'!H32 -> -91.162969 | I28: ='Side Calcs'!I32 -> -95.721117
A29: Veränderungerungen Nachrangkapital | D29: ='Side Calcs'!D40-'Side Calcs'!D37 -> 140 | E29: ='Side Calcs'!E40-'Side Calcs'!E37 -> 0 | F29: ='Side Calcs'!F40-'Side Calcs'!F37 -> 0 | G29: ='Side Calcs'!G40-'Side Calcs'!G37 -> 0 | H29: ='Side Calcs'!H40-'Side Calcs'!H37 -> 0 | I29: ='Side Calcs'!I40-'Side Calcs'!I37 -> 0
A30: Veränderungen bei den langfr. Bankverbindlichkeiten | D30: =Bilanz!D33-Bilanz!C33 -> 37.1875 | E30: =Bilanz!E33-Bilanz!D33 -> -92.460938 | F30: =Bilanz!F33-Bilanz!E33 -> -85.90332 | G30: =Bilanz!G33-Bilanz!F33 -> -70.165405 | H30: =Bilanz!H33-Bilanz!G33 -> -61.39473 | I30: =Bilanz!I33-Bilanz!H33 -> -53.720388
A31: Veränderungen bei den kurzfr. Bankverbindlichkeiten | D31: =Bilanz!D38-Bilanz!C38 -> -69.9 | E31: =Bilanz!E38-Bilanz!D38 -> 0 | F31: =Bilanz!F38-Bilanz!E38 -> 0 | G31: =Bilanz!G38-Bilanz!F38 -> 0 | H31: =Bilanz!H38-Bilanz!G38 -> 0 | I31: =Bilanz!I38-Bilanz!H38 -> 0
A32: Summe Finanzing Cashflow | D32: =SUM(D26:D31) -> 32.2875 | E32: =SUM(E26:E31) -> -171.21094 | F32: =SUM(F26:F31) -> -168.59082 | G32: =SUM(G26:G31) -> -156.98728 | H32: =SUM(H26:H31) -> -152.5577 | I32: =SUM(I26:I31) -> -149.44151
A34: Total Cashflow (Summe der einzelnen Positionen 1-3) | D34: =SUM(D18,D23,D32) -> 98.409308 | E34: =SUM(E18,E23,E32) -> 28.254858 | F34: =SUM(F18,F23,F32) -> 21.772846 | G34: =SUM(G18,G23,G32) -> 18.194417 | H34: =SUM(H18,H23,H32) -> 22.785521 | I34: =SUM(I18,I23,I32) -> 32.155573
A37: Cash Summary
A38: Beginning Cash balance | D38: =C40 -> 0 | E38: =D40 -> 98.409308 | F38: =E40 -> 126.66417 | G38: =F40 -> 148.43701 | H38: =G40 -> 166.63143 | I38: =H40 -> 189.41695
A39: Total Cashflow | D39: =D34 -> 98.409308 | E39: =E34 -> 28.254858 | F39: =F34 -> 21.772846 | G39: =G34 -> 18.194417 | H39: =H34 -> 22.785521 | I39: =I34 -> 32.155573
A40: Ending Cash Balance | C40: =Bilanz!C15-Bilanz!C39 -> 0 | D40: =SUM(D38:D39) -> 98.409308 | E40: =SUM(E38:E39) -> 126.66417 | F40: =SUM(F38:F39) -> 148.43701 | G40: =SUM(G38:G39) -> 166.63143 | H40: =SUM(H38:H39) -> 189.41695 | I40: =SUM(I38:I39) -> 221.57252

Sheet Side Calcs
A1: =Controls!A1 -> Forecast: Kundennamen
A2: {=MID(CELL("dateiname",A1),SEARCH("]",CELL("dateiname",A1))+1,31)} -> Side Calcs
A3: (TEUR) | B3: =Controls!B7 -> 45291 | C3: =DATE(YEAR(B3)+1,MONTH(B3),DAY(B3)) -> 45657 | D3: =DATE(YEAR(C3)+1,MONTH(C3),DAY(C3)) -> 46022 | E3: =DATE(YEAR(D3)+1,MONTH(D3),DAY(D3)) -> 46387 | F3: =DATE(YEAR(E3)+1,MONTH(E3),DAY(E3)) -> 46752 | G3: =DATE(YEAR(F3)+1,MONTH(F3),DAY(F3)) -> 47118 | H3: =DATE(YEAR(G3)+1,MONTH(G3),DAY(G3)) -> 47483 | I3: =DATE(YEAR(H3)+1,MONTH(H3),DAY(H3)) -> 47848
A5: Immaterielle Vermögenswerte
A6: Anfangsbestand | C6: =B9 -> 2.8 | D6: =C9 -> 4.2 | E6: =D9 -> 8.526 | F6: =E9 -> 14.42658 | G6: =F9 -> 22.428701 | H6: =G9 -> 33.23359 | I6: =H9 -> 47.774264
A7: Investitionen in imm. Vermögenswerte | C7: 2.8 | D7: ='Input (Annahmen)'!D30*GuV!D7 -> 2.94 | E7: ='Input (Annahmen)'!E30*GuV!E7 -> 3.087 | F7: ='Input (Annahmen)'!F30*GuV!F7 -> 3.24135 | G7: ='Input (Annahmen)'!G30*GuV!G7 -> 3.4034175 | H7: ='Input (Annahmen)'!H30*GuV!H7 -> 3.5735884 | I7: ='Input (Annahmen)'!I30*GuV!I7 -> 3.7522678
A8: Abschreibung | C8: 0.5 | D8: ='Input (Annahmen)'!D31*'Side Calcs'!D6 -> 1.386 | E8: ='Input (Annahmen)'!E31*'Side Calcs'!E6 -> 2.81358 | F8: ='Input (Annahmen)'!F31*'Side Calcs'!F6 -> 4.7607714 | G8: ='Input (Annahmen)'!G31*'Side Calcs'!G6 -> 7.4014715 | H8: ='Input (Annahmen)'!H31*'Side Calcs'!H6 -> 10.967085 | I8: ='Input (Annahmen)'!I31*'Side Calcs'!I6 -> 15.765507
A9: Endbestand | B9: =Bilanz!B7 -> 2.8 | C9: =Bilanz!C7 -> 4.2 | D9: =SUM(D6:D8) -> 8.526 | E9: =SUM(E6:E8) -> 14.42658 | F9: =SUM(F6:F8) -> 22.428701 | G9: =SUM(G6:G8) -> 33.23359 | H9: =SUM(H6:H8) -> 47.774264 | I9: =SUM(I6:I8) -> 67.292038
A11: Sachanlagevermögen
A12: Anfangsbestand | C12: =Bilanz!B8 -> 3810.8 | D12: =Bilanz!C8 -> 4061.7 | E12: =Bilanz!D8 -> 3955.6288 | F12: =Bilanz!E8 -> 3879.2763 | G12: =Bilanz!F8 -> 3830.161 | H12: =Bilanz!G8 -> 3806.1267 | I12: =Bilanz!H8 -> 3805.308
A13: Investitionen ins Sachanlagevermögen | C13: 304.7 | D13: ='Input (Annahmen)'!D32*GuV!D7 -> 354.0516 | E13: ='Input (Annahmen)'!E32*GuV!E7 -> 371.75418 | F13: ='Input (Annahmen)'!F32*GuV!F7 -> 390.34189 | G13: ='Input (Annahmen)'!G32*GuV!G7 -> 409.85898 | H13: ='Input (Annahmen)'!H32*GuV!H7 -> 430.35193 | I13: ='Input (Annahmen)'!I32*GuV!I7 -> 451.86953
A14: Abschreibungen | B14: 14 | C14: =GuV!C18 -> -431.7 | D14: ='Input (Annahmen)'!D33*'Side Calcs'!D12 -> -460.12278 | E14: ='Input (Annahmen)'!E33*'Side Calcs'!E12 -> -448.10669 | F14: ='Input (Annahmen)'!F33*'Side Calcs'!F12 -> -439.45722 | G14: ='Input (Annahmen)'!G33*'Side Calcs'!G12 -> -433.89328 | H14: ='Input (Annahmen)'!H33*'Side Calcs'!H12 -> -431.17059 | I14: ='Input (Annahmen)'!I33*'Side Calcs'!I12 -> -431.07785
A15: Endbestand | B15: =Bilanz!B8 -> 3810.8 | C15: =Bilanz!C8 -> 4061.7 | D15: =SUM(D12:D14) -> 3955.6288 | E15: =SUM(E12:E14) -> 3879.2763 | F15: =SUM(F12:F14) -> 3830.161 | G15: =SUM(G12:G14) -> 3806.1267 | H15: =SUM(H12:H14) -> 3805.308 | I15: =SUM(I12:I14) -> 3826.0997
A17: Net Working Capital
A18: Vorräte | B18: =Bilanz!B12 -> 41 | C18: =Bilanz!C12 -> 105.7 | D18: =D19/Controls!$B$5*-GuV!D8 -> 45.832707 | E18: =E19/Controls!$B$5*-GuV!E8 -> 46.520198 | F18: =F19/Controls!$B$5*-GuV!F8 -> 48.846208 | G18: =G19/Controls!$B$5*-GuV!G8 -> 51.288518 | H18: =H19/Controls!$B$5*-GuV!H8 -> 53.852944 | I18: =I19/Controls!$B$5*-GuV!I8 -> 56.545591
A19: Lagerdauer im Durchschnitt in Tage | B19: =-B18/GuV!B8*Controls!$B$5 -> 11.883586 | C19: =-C18/GuV!C8*Controls!$B$5 -> 36.297394 | D19: ='Input (Annahmen)'!D34 -> 12.6 | E19: ='Input (Annahmen)'!E34 -> 12.6 | F19: ='Input (Annahmen)'!F34 -> 12.6 | G19: ='Input (Annahmen)'!G34 -> 12.6 | H19: ='Input (Annahmen)'!H34 -> 12.6 | I19: ='Input (Annahmen)'!I34 -> 12.6
A21: Forderungen aus Lieferung und Leistung | B21: =Bilanz!B13 -> 834.2 | C21: =Bilanz!C13 -> 546.9 | D21: =D22/Controls!$B$5*GuV!D7 -> 1091.2549 | E21: =E22/Controls!$B$5*GuV!E7 -> 1145.8177 | F21: =F22/Controls!$B$5*GuV!F7 -> 1203.1086 | G21: =G22/Controls!$B$5*GuV!G7 -> 1263.264 | H21: =H22/Controls!$B$5*GuV!H7 -> 1326.4272 | I21: =I22/Controls!$B$5*GuV!I7 -> 1392.7485
A22: Debitoren-Ziel | B22: =B21/GuV!B7*Controls!$B$5 -> 76.40536 | C22: =C21/GuV!C7*Controls!$B$5 -> 47.360198 | D22: ='Input (Annahmen)'!D35 -> 90 | E22: ='Input (Annahmen)'!E35 -> 90 | F22: ='Input (Annahmen)'!F35 -> 90 | G22: ='Input (Annahmen)'!G35 -> 90 | H22: ='Input (Annahmen)'!H35 -> 90 | I22: ='Input (Annahmen)'!I35 -> 90
A24: Lieferantenverbindlichkeiten | B24: =Bilanz!B37 -> 287.6 | C24: =Bilanz!C37 -> 214.4 | D24: =D25/Controls!$B$5*-GuV!D8 -> 109.12549 | E24: =E25/Controls!$B$5*-GuV!E8 -> 110.76238 | F24: =F25/Controls!$B$5*-GuV!F8 -> 116.30049 | G24: =G25/Controls!$B$5*-GuV!G8 -> 122.11552 | H24: =H25/Controls!$B$5*-GuV!H8 -> 128.22129 | I24: =I25/Controls!$B$5*-GuV!I8 -> 134.63236
A25: Kreditorenziel | B25: =B24/-GuV!B8*Controls!$B$5 -> 83.359009 | C25: =C24/-GuV!C8*Controls!$B$5 -> 73.624988 | D25: ='Input (Annahmen)'!D36 -> 30 | E25: ='Input (Annahmen)'!E36 -> 30 | F25: ='Input (Annahmen)'!F36 -> 30 | G25: ='Input (Annahmen)'!G36 -> 30 | H25: ='Input (Annahmen)'!H36 -> 30 | I25: ='Input (Annahmen)'!I36 -> 30
A27: Net Working Capital | B27: =B18+B21-B24 -> 587.6 | C27: =C18+C21-C24 -> 438.2 | D27: =D18+D21-D24 -> 1027.9621 | E27: =E18+E21-E24 -> 1081.5755 | F27: =F18+F21-F24 -> 1135.6543 | G27: =G18+G21-G24 -> 1192.437 | H27: =H18+H21-H24 -> 1252.0588 | I27: =I18+I21-I24 -> 1314.6618
A29: Bilanzgewinn
A30: Anfangsbestand | C30: =B33 -> 51 | D30: =C33 -> 91.8 | E30: =D33 -> 111.16122 | F30: =E33 -> 179.85456 | G30: =F33 -> 263.55322 | H30: =G33 -> 356.67613 | I30: =H33 -> 473.47051
A31: =GuV!A30 -> Überschuss für Thesaurierung und Ausschüttung | B31: =GuV!B30 -> 23.8 | C31: =GuV!C30 -> 143.6 | D31: =GuV!D30 -> 94.361219 | E31: =GuV!E30 -> 147.44335 | F31: =GuV!F30 -> 166.38616 | G31: =GuV!G30 -> 179.94478 | H31: =GuV!H30 -> 207.95735 | I31: =GuV!I30 -> 241.74325
A32: Ausschüttungen / Privatentnahmen | C32: 0 | D32: ='Input (Annahmen)'!D37 -> -75 | E32: ='Input (Annahmen)'!E37 -> -78.75 | F32: ='Input (Annahmen)'!F37 -> -82.6875 | G32: ='Input (Annahmen)'!G37 -> -86.821875 | H32: ='Input (Annahmen)'!H37 -> -91.162969 | I32: ='Input (Annahmen)'!I37 -> -95.721117
A33: Endbestand | B33: =Bilanz!B26 -> 51 | C33: =Bilanz!C26 -> 91.8 | D33: =SUM(D30:D32) -> 111.16122 | E33: =SUM(E30:E32) -> 179.85456 | F33: =SUM(F30:F32) -> 263.55322 | G33: =SUM(G30:G32) -> 356.67613 | H33: =SUM(H30:H32) -> 473.47051 | I33: =SUM(I30:I32) -> 619.49264
A36: Nachrangkapital
A37: Anfangsbestand | B37: =Bilanz!B29 -> -26.1 | C37: =B40 -> -26.1 | D37: =C40 -> -41.3 | E37: =D40 -> 98.7 | F37: =E40 -> 98.7 | G37: =F40 -> 98.7 | H37: =G40 -> 98.7 | I37: =H40 -> 98.7
A38: Erhöhungen | B38: ='Input (Annahmen)'!B38 -> 0 | C38: ='Input (Annahmen)'!C38 -> 0 | D38: ='Input (Annahmen)'!D38 -> 140 | E38: ='Input (Annahmen)'!E38 -> 0 | F38: ='Input (Annahmen)'!F38 -> 0 | G38: ='Input (Annahmen)'!G38 -> 0 | H38: ='Input (Annahmen)'!H38 -> 0 | I38: ='Input (Annahmen)'!I38 -> 0
A39: Tilgungen | B39: ='Input (Annahmen)'!B39 -> 0 | C39: ='Input (Annahmen)'!C39 -> 0 | D39: ='Input (Annahmen)'!D39 -> 0 | E39: ='Input (Annahmen)'!E39 -> 0 | F39: ='Input (Annahmen)'!F39 -> 0 | G39: ='Input (Annahmen)'!G39 -> 0 | H39: ='Input (Annahmen)'!H39 -> - | I39: ='Input (Annahmen)'!I39 -> 0
A40: Endbestand | B40: =Bilanz!B29 -> -26.1 | C40: =Bilanz!C29 -> -41.3 | D40: =SUM(D37:D39) -> 98.7 | E40: =SUM(E37:E39) -> 98.7 | F40: =SUM(F37:F39) -> 98.7 | G40: =SUM(G37:G39) -> 98.7 | H40: =SUM(H37:H39) -> 98.7 | I40: =SUM(I37:I39) -> 98.7
A42: Kurzfristige Bankverbindlichkeiten (inkl. Revolver) | B42: =SUM(Bilanz!B38:B39) -> 259.9 | C42: =SUM(Bilanz!C38:C39) -> 69.9 | D42: =SUM(Bilanz!D38:D39) -> 0 | E42: =SUM(Bilanz!E38:E39) -> 0 | F42: =SUM(Bilanz!F38:F39) -> 0 | G42: =SUM(Bilanz!G38:G39) -> 0 | H42: =SUM(Bilanz!H38:H39) -> 0 | I42: =SUM(Bilanz!I38:I39) -> 0
A43: Langfristige Bankverbindlichkeiten | B43: =Bilanz!B33 -> 3414.5 | C43: =Bilanz!C33 -> 3382.5 | D43: =Bilanz!D33 -> 3419.6875 | E43: =Bilanz!E33 -> 3327.2266 | F43: =Bilanz!F33 -> 3241.3232 | G43: =Bilanz!G33 -> 3171.1578 | H43: =Bilanz!H33 -> 3109.7631 | I43: =Bilanz!I33 -> 3056.0427

Sheet Debt schedule
A1: =Controls!A1 -> Forecast: Kundennamen
A2: {=MID(CELL("dateiname",A1),SEARCH("]",CELL("dateiname",A1))+1,31)} -> Debt schedule
A3: (TEUR) | B3: =Controls!B7 -> 45291 | C3: =DATE(YEAR(B3)+1,MONTH(B3),DAY(B3)) -> 45657 | D3: =DATE(YEAR(C3)+1,MONTH(C3),DAY(C3)) -> 46022 | E3: =DATE(YEAR(D3)+1,MONTH(D3),DAY(D3)) -> 46387 | F3: =DATE(YEAR(E3)+1,MONTH(E3),DAY(E3)) -> 46752 | G3: =DATE(YEAR(F3)+1,MONTH(F3),DAY(F3)) -> 47118 | H3: =DATE(YEAR(G3)+1,MONTH(G3),DAY(G3)) -> 47483 | I3: =DATE(YEAR(H3)+1,MONTH(H3),DAY(H3)) -> 47848
A5: Langfristige Bankverbindlichkeiten
A6: Anfangsbestand | C6: =B9 -> 3414.5 | D6: =C9 -> 3382.5 | E6: =D9 -> 3419.6875 | F6: =E9 -> 3327.2266 | G6: =F9 -> 3241.3232 | H6: =G9 -> 3171.1578 | I6: =H9 -> 3109.7631
A7: Neuaufnahme | D7: ='Input (Annahmen)'!D44 -> 460 | E7: ='Input (Annahmen)'!E44 -> 335 | F7: ='Input (Annahmen)'!F44 -> 330 | G7: ='Input (Annahmen)'!G44 -> 335 | H7: ='Input (Annahmen)'!H44 -> 335 | I7: ='Input (Annahmen)'!I44 -> 335
A8: Tilgungen | D8: ='Input (Annahmen)'!D45 -> -422.8125 | E8: ='Input (Annahmen)'!E45 -> -427.46094 | F8: ='Input (Annahmen)'!F45 -> -415.90332 | G8: ='Input (Annahmen)'!G45 -> -405.16541 | H8: ='Input (Annahmen)'!H45 -> -396.39473 | I8: ='Input (Annahmen)'!I45 -> -388.72039
A9: Endbestand | B9: =Bilanz!B33 -> 3414.5 | C9: =Bilanz!C33 -> 3382.5 | D9: =SUM(D6:D8) -> 3419.6875 | E9: =SUM(E6:E8) -> 3327.2266 | F9: =SUM(F6:F8) -> 3241.3232 | G9: =SUM(G6:G8) -> 3171.1578 | H9: =SUM(H6:H8) -> 3109.7631 | I9: =SUM(I6:I8) -> 3056.0427
A11: Zinsaufwand | D11: =D12*(AVERAGE(C9:D9)) -> -119.03828 | E11: =E12*(AVERAGE(D9:E9)) -> -126.50464 | F11: =F12*(AVERAGE(E9:F9)) -> -131.371 | G11: =G12*(AVERAGE(F9:G9)) -> -160.31203 | H11: =H12*(AVERAGE(G9:H9)) -> -157.02302 | I11: =I12*(AVERAGE(H9:I9)) -> -154.14515
A12: Durchschnitt. Verzinsung Bankverbindlichkeiten | C12: =GuV!C22/AVERAGE(SUM(Bilanz!B33, Bilanz!B38), SUM(Bilanz!C33,Bilanz!C38)) -> -0.028876915 | D12: ='Input (Annahmen)'!D46 -> -0.035 | E12: ='Input (Annahmen)'!E46 -> -0.0375 | F12: ='Input (Annahmen)'!F46 -> -0.04 | G12: ='Input (Annahmen)'!G46 -> -0.05 | H12: ='Input (Annahmen)'!H46 -> -0.05 | I12: ='Input (Annahmen)'!I46 -> -0.05
A15: Kurzfristige Bankverbindlichkeiten
A16: Anfangsbestand | C16: =B19 -> 259.9 | D16: =C19 -> 69.9 | E16: =D19 -> 0 | F16: =E19 -> 0 | G16: =F19 -> 0 | H16: =G19 -> 0 | I16: =H19 -> 0
A17: Neuaufnahme | D17: ='Input (Annahmen)'!D47 -> 0 | E17: ='Input (Annahmen)'!E47 -> 0 | F17: ='Input (Annahmen)'!F47 -> 0 | G17: ='Input (Annahmen)'!G47 -> 0 | H17: ='Input (Annahmen)'!H47 -> 0 | I17: ='Input (Annahmen)'!I47 -> 0
A18: Rückzahlungen | D18: ='Input (Annahmen)'!D48 -> -69.9 | E18: ='Input (Annahmen)'!E48 -> 0 | F18: ='Input (Annahmen)'!F48 -> 0 | G18: ='Input (Annahmen)'!G48 -> 0 | H18: ='Input (Annahmen)'!H48 -> 0 | I18: ='Input (Annahmen)'!I48 -> 0
A19: Endbestand | B19: =Bilanz!B38 -> 259.9 | C19: =Bilanz!C38 -> 69.9 | D19: =SUM(D16:D18) -> 0 | E19: =SUM(E16:E18) -> 0 | F19: =SUM(F16:F18) -> 0 | G19: =SUM(G16:G18) -> 0 | H19: =SUM(H16:H18) -> 0 | I19: =SUM(I16:I18) -> 0
A21: Zinsaufwand | D21: =D22*AVERAGE(C19:D19) -> -1.22325 | E21: =E22*AVERAGE(D19:E19) -> 0 | F21: =F22*AVERAGE(E19:F19) -> 0 | G21: =G22*AVERAGE(F19:G19) -> 0 | H21: =H22*AVERAGE(G19:H19) -> 0 | I21: =I22*AVERAGE(H19:I19) -> 0
A22: Durchschnittl. Verzinsung Bankverbindlichkeiten | C22: ='Input (Annahmen)'!C46 -> -0.028876915 | D22: ='Input (Annahmen)'!D46 -> -0.035 | E22: ='Input (Annahmen)'!E46 -> -0.0375 | F22: ='Input (Annahmen)'!F46 -> -0.04 | G22: ='Input (Annahmen)'!G46 -> -0.05 | H22: ='Input (Annahmen)'!H46 -> -0.05 | I22: ='Input (Annahmen)'!I46 -> -0.05
A25: Revolver | B25: =Bilanz!B39 -> 0 | C25: =Bilanz!C39 -> 0 | D25: =Bilanz!D39 -> 0 | E25: =Bilanz!E39 -> 0 | F25: =Bilanz!F39 -> 0 | G25: =Bilanz!G39 -> 0 | H25: =Bilanz!H39 -> 0 | I25: =Bilanz!I39 -> 0
A27: Zinsaufwand für Revolver | D27: =D28*AVERAGE(C25:D25) -> 0 | E27: =E28*AVERAGE(D25:E25) -> 0 | F27: =F28*AVERAGE(E25:F25) -> 0 | G27: =G28*AVERAGE(F25:G25) -> 0 | H27: =H28*AVERAGE(G25:H25) -> 0 | I27: =I28*AVERAGE(H25:I25) -> 0
A28: Zinssatz Revolver | B28: ='Input (Annahmen)'!B49 -> 0 | C28: ='Input (Annahmen)'!C49 -> -0.028876915 | D28: ='Input (Annahmen)'!D49 -> -0.1 | E28: ='Input (Annahmen)'!E49 -> -0.1 | F28: ='Input (Annahmen)'!F49 -> -0.1 | G28: ='Input (Annahmen)'!G49 -> -0.1 | H28: ='Input (Annahmen)'!H49 -> -0.1 | I28: ='Input (Annahmen)'!I49 -> -0.1
A31: Kassenbestand / Bankguthaben (cash) | B31: =Bilanz!B16 -> 26.4 | C31: =Bilanz!C16 -> 34.5 | D31: =Bilanz!D16 -> 48.682095 | E31: =Bilanz!E16 -> 51.1162 | F31: =Bilanz!F16 -> 53.67201 | G31: =Bilanz!G16 -> 56.35561 | H31: =Bilanz!H16 -> 59.173391 | I31: =Bilanz!I16 -> 62.13206
A33: Zinsgutschrift für Guthaben | D33: =D34*AVERAGE(C31:D31) -> 0 | E33: =E34*AVERAGE(D31:E31) -> 0 | F33: =F34*AVERAGE(E31:F31) -> 0 | G33: =G34*AVERAGE(F31:G31) -> 0 | H33: =H34*AVERAGE(G31:H31) -> 0 | I33: =I34*AVERAGE(H31:I31) -> 0
A34: Zinssatz für Guthaben | C34: =GuV!C21/AVERAGE(Bilanz!B16:C16) -> 0 | D34: ='Input (Annahmen)'!D50 -> 0 | E34: ='Input (Annahmen)'!E50 -> 0 | F34: ='Input (Annahmen)'!F50 -> 0 | G34: ='Input (Annahmen)'!G50 -> 0 | H34: ='Input (Annahmen)'!H50 -> 0 | I34: ='Input (Annahmen)'!I50 -> 0
